<?xml version="1.0" ?>
<!-- =================================================================================== -->
<!-- |    This document was autogenerated by xacro from robo.urdf.xacro                | -->
<!-- |    EDITING THIS FILE BY HAND IS NOT RECOMMENDED                                 | -->
<!-- =================================================================================== -->
<robot name="robobase">
  <link name="base_footprint">
    <origin rpy="0 0 0" xyz="-0.5 0 0"/>
  </link>
  <!-- Base Link -->
  <joint name="base_joint" type="fixed">
    <parent link="base_footprint"/>
    <child link="base_link"/>
    <origin rpy="0 0 0" xyz="0.5 0 0"/>
  </joint>
  <link name="base_link">
    <inertial>
      <origin rpy="0 0 0" xyz="0 0 0.1"/>
      <mass value="297.00000000000006"/>
      <inertia ixx="8.476875000000001" ixy="0" ixz="0" iyy="25.740000000000006" iyz="0" izz="32.236875000000005"/>
    </inertial>
    <visual>
      <origin rpy="0 0 0" xyz="0 0 0.1"/>
      <geometry>
        <box size="1 0.55 0.2"/>
      </geometry>
      <material name="gray">
        <color rgba="0.5 0.5 0.5 1.0"/>
      </material>
    </visual>
    <collision>
      <origin rpy="0 0 0" xyz="0 0 0.1"/>
      <geometry>
        <box size="1 0.55 0.2"/>
      </geometry>
    </collision>
  </link>
  <!-- Lfwheel Link -->
  <joint name="lfwheel_joint" type="continuous">
    <parent link="base_link"/>
    <child link="lfwheel_link"/>
    <origin rpy="0 0 0" xyz="0.5 0.275 0"/>
  </joint>
  <link name="lfwheel_link">
    <inertial>
      <origin rpy="0 0 0" xyz="0 0 0"/>
      <mass value="11.309733552923257"/>
      <inertia ixx="0.04523893421169303" ixy="0" ixz="0" iyy="0.04523893421169303" iyz="0" izz="0.04523893421169303"/>
    </inertial>
    <visual>
      <origin rpy="0 0 0" xyz="0 0 0"/>
      <geometry>
        <sphere radius="0.1"/>
      </geometry>
      <material name="black">
        <color rgba="0.0 0.0 0.0 1.0"/>
      </material>
    </visual>
    <collision>
      <origin rpy="0 0 0" xyz="0 0 0"/>
      <geometry>
        <sphere radius="0.1"/>
      </geometry>
    </collision>
  </link>
  <gazebo reference="lfwheel_link">
    <mu1>0.0</mu1>
    <mu2>0.0</mu2>
    <material>Gazebo/Black</material>
  </gazebo>
  <!-- Rfwheel Link -->
  <joint name="rfwheel_joint" type="continuous">
    <parent link="base_link"/>
    <child link="rfwheel_link"/>
    <origin rpy="0 0 0" xyz="0.5 -0.275 0"/>
  </joint>
  <link name="rfwheel_link">
    <inertial>
      <origin rpy="0 0 0" xyz="0 0 0"/>
      <mass value="11.309733552923257"/>
      <inertia ixx="0.04523893421169303" ixy="0" ixz="0" iyy="0.04523893421169303" iyz="0" izz="0.04523893421169303"/>
    </inertial>
    <visual>
      <origin rpy="0 0 0" xyz="0 0 0"/>
      <geometry>
        <sphere radius="0.1"/>
      </geometry>
      <material name="black">
        <color rgba="0.0 0.0 0.0 1.0"/>
      </material>
    </visual>
    <collision>
      <origin rpy="0 0 0" xyz="0 0 0"/>
      <geometry>
        <sphere radius="0.1"/>
      </geometry>
    </collision>
  </link>
  <gazebo reference="rfwheel_link">
    <mu1>0.0</mu1>
    <mu2>0.0</mu2>
    <material>Gazebo/Black</material>
  </gazebo>
  <!-- Lbwheel Link -->
  <joint name="lbwheel_joint" type="continuous">
    <parent link="base_link"/>
    <child link="lbwheel_link"/>
    <origin rpy="-1.5707963267948966 0 0" xyz="-0.5 0.275 0.1"/>
    <axis xyz="0 0 1"/>
    <limit effort="1000" velocity="1000"/>
    <dynamics damping="1.0" friction="1.0"/>
  </joint>
  <link name="lbwheel_link">
    <inertial>
      <origin rpy="0 0 0" xyz="0 0 0.1"/>
      <mass value="67.85840131753955"/>
      <inertia ixx="0.9047786842338608" ixy="0" ixz="0" iyy="0.9047786842338608" iyz="0" izz="1.357168026350791"/>
    </inertial>
    <visual>
      <origin rpy="0 0 0" xyz="0 0 0.1"/>
      <geometry>
        <cylinder length="0.2" radius="0.2"/>
      </geometry>
      <material name="black">
        <color rgba="0.0 0.0 0.0 1.0"/>
      </material>
    </visual>
    <collision>
      <origin rpy="0 0 0" xyz="0 0 0.1"/>
      <geometry>
        <cylinder length="0.2" radius="0.2"/>
      </geometry>
    </collision>
  </link>
  <gazebo reference="lbwheel_link">
    <mu1>3.0</mu1>
    <mu2>3.0</mu2>
    <material>Gazebo/Black</material>
  </gazebo>
  <!-- Rbwheel Link -->
  <joint name="rbwheel_joint" type="continuous">
    <parent link="base_link"/>
    <child link="rbwheel_link"/>
    <origin rpy="1.5707963267948966 0 0" xyz="-0.5 -0.275 0.1"/>
    <axis xyz="0 0 -1"/>
    <limit effort="1000" velocity="1000"/>
    <dynamics damping="1.0" friction="1.0"/>
  </joint>
  <link name="rbwheel_link">
    <inertial>
      <origin rpy="0 0 0" xyz="0 0 0.1"/>
      <mass value="67.85840131753955"/>
      <inertia ixx="0.9047786842338608" ixy="0" ixz="0" iyy="0.9047786842338608" iyz="0" izz="1.357168026350791"/>
    </inertial>
    <visual>
      <origin rpy="0 0 0" xyz="0 0 0.1"/>
      <geometry>
        <cylinder length="0.2" radius="0.2"/>
      </geometry>
      <material name="black">
        <color rgba="0.0 0.0 0.0 1.0"/>
      </material>
    </visual>
    <collision>
      <origin rpy="0 0 0" xyz="0 0 0.1"/>
      <geometry>
        <cylinder length="0.2" radius="0.2"/>
      </geometry>
    </collision>
  </link>
  <gazebo reference="rbwheel_link">
    <mu1>3.0</mu1>
    <mu2>3.0</mu2>
    <material>Gazebo/Black</material>
  </gazebo>
  <gazebo>
    <plugin filename="libgz_ros2_control-system.so" name="gz_ros2_control::GazeboSimROS2ControlPlugin">
      <parameters>/root/robows/src/robobase/mobilerobo/config/controllers.yaml</parameters>
    </plugin>
  </gazebo>
  <ros2_control name="GazeboSystem" type="system">
    <hardware>
      <plugin>gz_ros2_control/GazeboSimSystem</plugin>
    </hardware>
    <joint name="lfwheel_joint">
      <state_interface name="position"/>
      <state_interface name="velocity"/>
    </joint>
    <joint name="rfwheel_joint">
      <state_interface name="position"/>
      <state_interface name="velocity"/>
    </joint>
    <joint name="lbwheel_joint">
      <command_interface name="velocity">
        <param name="min">-100</param>
        <param name="max">100</param>
      </command_interface>
      <state_interface name="position"/>
      <state_interface name="velocity"/>
    </joint>
    <joint name="rbwheel_joint">
      <command_interface name="velocity">
        <param name="min">-100</param>
        <param name="max">100</param>
      </command_interface>
      <state_interface name="position"/>
      <state_interface name="velocity"/>
    </joint>
  </ros2_control>
  <!-- Camera joint (fixed to parent, e.g., base_link) -->
  <joint name="camera_joint" type="fixed">
    <parent link="base_link"/>
    <child link="camera_link"/>
    <origin rpy="0 0 0" xyz="0.525 0 0.175"/>
  </joint>
  <!-- Camera link -->
  <link name="camera_link">
    <visual>
      <geometry>
        <box size="0.05 0.05 0.05"/>
      </geometry>
      <material name="black"/>
    </visual>
    <collision>
      <geometry>
        <box size="0.05 0.05 0.05"/>
      </geometry>
    </collision>
    <inertial>
      <mass value="0.1"/>
      <inertia ixx="0.0001" ixy="0.0" ixz="0.0" iyy="0.0001" iyz="0.0" izz="0.0001"/>
    </inertial>
  </link>
  <!-- Example sensor tag (optional, can be removed or customized) -->
  <gazebo reference="camera_link">
    <sensor name="camera_sensor" type="camera">
      <camera>
        <horizontal_fov>1.047</horizontal_fov>
        <image>
          <width>640</width>
          <height>480</height>
          <format>R8G8B8</format>
        </image>
        <clip>
          <near>0.1</near>
          <far>100</far>
        </clip>
        <!-- Add camera_info_topic for ROS info -->
        <camera_info_topic>camera/camera_info</camera_info_topic>
      </camera>
      <always_on>1</always_on>
      <update_rate>30</update_rate>
      <visualize>true</visualize>
      <topic>camera/image_raw</topic>
      <gz_frame_id>camera_link</gz_frame_id>
      <!-- Frame id for ROS -->
    </sensor>
  </gazebo>
  <gazebo>
    <plugin filename="gz-sim-sensors-system" name="gz::sim::systems::Sensors">
      <render_engine>ogre2</render_engine>
    </plugin>
  </gazebo>
  <!-- Lidar joint -->
  <joint name="lidar_joint" type="fixed">
    <parent link="base_link"/>
    <child link="lidar_link"/>
    <origin rpy="0 0 0" xyz="0 0 0.31000000000000005"/>
  </joint>
  <!-- Lidar link (simple cylinder visual/collision) -->
  <link name="lidar_link">
    <visual>
      <origin rpy="0 0 0" xyz="0 0 0"/>
      <geometry>
        <cylinder length="0.2" radius="0.07"/>
      </geometry>
      <material name="black">
        <color rgba="0 0 0 1"/>
      </material>
    </visual>
    <collision>
      <origin rpy="0 0 0" xyz="0 0 0"/>
      <geometry>
        <cylinder length="0.2" radius="0.07"/>
      </geometry>
    </collision>
    <inertial>
      <mass value="0.5"/>
      <origin rpy="0 0 0" xyz="0 0 0.05"/>
      <inertia ixx="0.001" ixy="0" ixz="0" iyy="0.001" iyz="0" izz="0.001"/>
    </inertial>
  </link>
  <gazebo reference="lidar_link">
    <sensor name="lidar_sensor" type="gpu_lidar">
      <always_on>true</always_on>
      <visualize>true</visualize>
      <update_rate>10</update_rate>
      <topic>scan</topic>
      <gz_frame_id>lidar_link</gz_frame_id>
      <lidar>
        <scan>
          <horizontal>
            <samples>360</samples>
            <resolution>1.000000</resolution>
            <min_angle>0.000000</min_angle>
            <max_angle>6.280000</max_angle>
          </horizontal>
        </scan>
        <range>
          <min>0.1</min>
          <max>8</max>
          <resolution>0.015000</resolution>
        </range>
        <noise>
          <type>gaussian</type>
          <mean>0.0</mean>
          <stddev>0.01</stddev>
        </noise>
      </lidar>
    </sensor>
  </gazebo>
  <joint name="imu_joint" type="fixed">
    <parent link="base_link"/>
    <child link="imu_link"/>
    <pose>0.05 0 0.05 0 0 0</pose>
    <axis>
      <xyz>0 0 1</xyz>
    </axis>
  </joint>
  <link name="imu_link"/>
  <gazebo reference="imu_link">
    <sensor name="imu_sensor" type="imu">
      <always_on>true</always_on>
      <update_rate>200</update_rate>
      <topic>imu</topic>
      <imu>
        <angular_velocity>
          <x>
            <noise type="gaussian">
              <mean>0.0</mean>
              <stddev>2e-4</stddev>
            </noise>
          </x>
          <y>
            <noise type="gaussian">
              <mean>0.0</mean>
              <stddev>2e-4</stddev>
            </noise>
          </y>
          <z>
            <noise type="gaussian">
              <mean>0.0</mean>
              <stddev>2e-4</stddev>
            </noise>
          </z>
        </angular_velocity>
        <linear_acceleration>
          <x>
            <noise type="gaussian">
              <mean>0.0</mean>
              <stddev>1.7e-2</stddev>
            </noise>
          </x>
          <y>
            <noise type="gaussian">
              <mean>0.0</mean>
              <stddev>1.7e-2</stddev>
            </noise>
          </y>
          <z>
            <noise type="gaussian">
              <mean>0.0</mean>
              <stddev>1.7e-2</stddev>
            </noise>
          </z>
        </linear_acceleration>
      </imu>
    </sensor>
  </gazebo>
</robot>
